Workbook

Sheet Pratique_Nettoyage
A1: ID | B1: Nom | C1: Ville | D1: Salaire | E1: Date
A2: 1 | B2: Awa Ndiaye | C2: Dakar | D2: 350000 | E2: 46034 | F2: =PROPER(TRIM(C2)) -> Dakar
A3: 2 | B3: Mamadou Diop | C3: Dakar | D3: 400000 | E3: 46037 | F3: =TRIM(C2) -> Dakar
A4: 3 | B4: Fatou Fall | C4: Thiès | E4: 46040
A5: 3 | B5: Fatou Fall | C5: Thiès | E5: 46040
A6: 4 | B6: Cheikh Ba | C6: Dakar | D6: 450000 | E6: 46042 | F6: =PROPER("dakar") -> Dakar
A7: 5 | B7: Mariama Sow | C7: Dakar | D7: 325000 | E7: 46044

Sheet Raw_Data
A1: order_id | B1: order_date | C1: customer_email | D1: country | E1: channel | F1: product_sku | G1: product_name | H1: quantity | I1: unit_price | J1: order_total | K1: weight | L1: currency | M1: status
A2: ORD-101805 | B2: 46100 | C2: customer0457@example.com | D2: France | E2: direct | F2: FR-9902 | G2: Trekking Poles | H2: 1 | I2: 45.00 | J2: 36.00 | K2: 520 | L2: EUR | M2: completed
A3: ORD-102690 | B3: 46161 | C3: customer0814@example.com | D3: France | E3: social | F3: FR-2210 | G3: Trail Softshell | H3: 1 | I3: 71.10 | J3: 71.10 | K3: 0.520 | L3: GBP | M3: completed
A4: ORD-101454 | B4: 46187 | C4: customer0858@example.com | D4: UK | E4: email | F4: FR-1120 | G4: Fell Runner Cap | H4: 1 | I4: 45.00 | J4: 45.00 | K4: 0.085 | L4: GBP | M4: completed
A5: ORD-100450 | B5: 46030 | C5: customer0116@example.com | D5: UK | E5: organic | F5: FR-5567 | G5: Merino Base Layer | H5: 1 | I5: 71.10 | J5: 71.10 | K5: 190 | L5: EUR | M5: completed
A6: ORD-101501 | B6: 46162 | C6: customer1397@example.com | D6: Ireland | E6: email | F6: FR-8890 | G6: Summit Down Gilet | H6: 1 | I6: 21.60 | J6: 21.60 | K6: 0.380 | L6: GBP | M6: completed
A7: ORD-101788 | B7: 46095 | C7: customer0775@example.com | D7: GB | E7: organic | F7: FR-1120 | G7: Fell Runner Cap | H7: 1 | I7: 45.00 | J7: 45.00 | K7: 85 | L7: GBP | M7: completed
A8: ORD-102657 | B8: 46137 | C8: customer1328@example.com | D8: GB | E8: social | F8: FR-1120 | G8: Fell Runner Cap | H8: 3 | I8: 85.50 | J8: 256.50 | K8: 0.085 | L8: GBP | M8: refunded
A9: ORD-102047 | B9: 46162 | C9: customer0760@example.com | D9: ireland | E9: organic | F9: FR-1120 | G9: Fell Runner Cap | H9: 2 | I9: 134.10 | J9: 268.20 | K9: 0.085 | L9: EUR | M9: refunded
A10: ORD-102650 | B10: 46114 | C10: customer0013@example.com | D10: gb | E10: paid_search | F10: FR-5567 | G10: Merino Base Layer | H10: 1 | I10: 24.00 | J10: 24.00 | K10: 190 | L10: GBP | M10: completed
A11: ORD-102734 | B11: 46069 | C11: customer0805@example.com | D11: UK | E11: paid_search | F11: FR-5567 | G11: Merino Base Layer | H11: 1 | I11: 95.00 | J11: 95.00 | K11: 190 | L11: EUR | M11: refunded
A12: ORD-102012 | B12: 46133 | C12: customer0123@example.com | D12: UK | E12: email | F12: FR-7781 | G12: Storm Overtrousers | H12: 1 | I12: 45.00 | J12: 45.00 | K12: 0.410 | L12: GBP | M12: completed
A13: ORD-102152 | B13: 46204 | C13: customer0956@example.com | D13: Ireland | E13: email | F13: FR-7781 | G13: Storm Overtrousers | H13: 1 | I13: 129.00 | J13: 129.00 | K13: 410 | L13: GBP | M13: completed
A14: ORD-102773 | B14: 02/27/2026 | C14: customer1363@example.com | D14: GB | E14: organic | F14: FR-3345 | G14: CafÃ© Latte Mug | H14: 3 | I14: 116.10 | J14: 348.30 | K14: 340 | L14: GBP | M14: refunded
A15: ORD-102215 | B15: 46074 | C15: customer1206@example.com | D15: gb | E15: direct | F15: FR-4471 | G15: Alpine Jacket | H15: 3 | I15: 129.00 | J15: 387.00 | K15: 640 | L15: GBP | M15: completed
A16: ORD-100612 | B16: 46208 | C16: customer0555@example.com | D16: uk | E16: email | F16: FR-2210 | G16: Trail Softshell | H16: 1 | I16: 45.00 | J16: 45.00 | K16: 0.520 | L16: EUR | M16: completed
A17: ORD-102771 | B17: 46033 | C17: customer1312@example.com | D17: Ireland | E17: paid_search | F17: FR-1120 | G17: Fell Runner Cap | H17: 1 | I17: 71.10 | J17: 71.10 | K17: 85 | L17: GBP | M17: completed
A18: ORD-101929 | B18: 46192 | C18: customer0084@example.com | D18: United Kingdom | E18: organic | F18: FR-7781 | G18: Storm Overtrousers | H18: 1 | I18: 116.10 | J18: 116.10 | K18: 0.410 | L18: GBP | M18: completed
A19: ORD-101855 | B19: 46180 | C19: customer0527@example.com | D19: GB | E19: paid_search | F19: FR-3345 | G19: CafÃ© Latte Mug | H19: 1 | I19: 89.00 | J19: 89.00 | K19: 0.340 | L19: GBP | M19: refunded
A20: ORD-101033 | B20: 46135 | C20: customer0970@example.com | D20: UK | E20: organic | F20: FR-4471 | G20: Alpine Jacket | H20: 2 | I20: 149.00 | J20: 298.00 | K20: 0.640 | L20: GBP | M20: completed
A21: ORD-100485 | B21: 46187 | C21: customer1056@example.com | D21: uk | E21: email | F21: FR-5567 | G21: Merino Base Layer | H21: 1 | I21: 45.00 | J21: 45.00 | K21: 0.190 | L21: GBP | M21: completed
A22: ORD-101121 | B22: 46109 | C22: customer0910@example.com | D22: France | E22: direct | F22: FR-5567 | G22: Merino Base Layer | H22: 1 | I22: 85.50 | J22: 85.50 | K22: 190 | L22: GBP | M22: completed
A23: ORD-101302 | B23: 46081 | C23: customer1155@example.com | D23: Germany | E23: email | F23: FR-8890 | G23: Summit Down Gilet | H23: 2 | I23: 149.00 | J23: 298.00 | K23: 380 | L23: GBP | M23: completed
A24: ORD-100778 | B24: 46069 | C24: customer1044@example.com | D24: uk | E24: social | F24: FR-1120 | G24: Fell Runner Cap | H24: 1 | I24: 21.60 | J24: 21.60 | K24: 85 | L24: GBP | M24: completed
A25: ORD-100968 | B25: 03/21/2026 | C25: customer0047@example.com | D25: ireland | E25: organic | F25: FR-3345 | G25: CafÃ© Latte Mug | H25: 1 | I25: 21.60 | J25: 21.60 | K25: 340 | L25: GBP | M25: completed
A26: ORD-101676 | B26: 46113 | C26: customer0180@example.com | D26: gb | E26: email | F26: FR-7781 | G26: Storm Overtrousers | H26: -1 | I26: 129.00 | J26: -129.00 | K26: 410 | L26: GBP | M26: completed
A27: ORD-102809 | B27: 46135 | C27: customer0212@example.com | D27: Germany | E27: organic | F27: FR-5567 | G27: Merino Base Layer | H27: 3 | I27: 89.00 | J27: 267.00 | K27: 0.190 | L27: EUR | M27: completed
A28: ORD-102890 | B28: 46031 | C28: customer0605@example.com | D28: UK | E28: direct | F28: FR-3345 | G28: CafÃ© Latte Mug | H28: 1 | I28: 21.60 | J28: 21.60 | K28: 340 | L28: GBP | M28: refunded
A29: ORD-100039 | B29: 46173 | C29: customer0449@example.com | D29: UK | E29: social | F29: FR-8890 | G29: Summit Down Gilet | H29: 2 | I29: 79.00 | J29: 158.00 | K29: 0.380 | L29: GBP | M29: completed
A30: ORD-102776 | B30: 46203 | C30: customer0321@example.com | D30: GB | E30: direct | F30: FR-8890 | G30: Summit Down Gilet | H30: 3 | I30: 11.25 | J30: 33.75 | K30: 0.380 | L30: GBP | M30: completed
A31: ORD-100053 | B31: 46116 | C31: customer1166@example.com | D31: gb | E31: social | F31: FR-2210 | G31: Trail Softshell | H31: 1 | I31: GBP45.00 | J31: 36.00 | K31: 520 | L31: GBP | M31: completed
A32: ORD-101914 | B32: 46094 | C32: customer0347@example.com | D32: Germany | E32: paid_search | F32: FR-5567 | G32: Merino Base Layer | H32: 2 | I32: 129.00 | J32: 258.00 | K32: 190 | L32: GBP | M32: completed
A33: ORD-100303 | B33: 46039 | C33: customer1186@example.com | D33: UK | E33: social | F33: FR-4471 | G33: Alpine Jacket | H33: 1 | I33: 71.10 | J33: 71.10 | K33: 640 | L33: GBP | M33: completed
A34: ORD-102075 | B34: 46113 | C34: customer1029@example.com | D34: UK | E34: organic | F34: FR-3345 | G34: CafÃ© Latte Mug | H34: -2 | I34: 45.00 | J34: -90.00 | K34: 340 | L34: GBP | M34: completed
A35: ORD-101025 | B35: 46068 | C35: customer1144@example.com | D35: United Kingdom | E35: email | F35: FR-4471 | G35: Alpine Jacket | H35: 2 | I35: £80.10 | J35: 160.20 | K35: 640 | L35: EUR | M35: completed
A36: ORD-101946 | B36: 46152 | C36: customer1248@example.com | D36: UK | E36: organic | F36: FR-4471 | G36: Alpine Jacket | H36: 2 | I36: GBP12.50 | J36: 25.00 | K36: 0.640 | L36: GBP | M36: completed
A37: ORD-101075 | B37: 03/19/2026 | C37: customer0388@example.com | D37: UK | E37: organic | F37: FR-7781 | G37: Storm Overtrousers | H37: 3 | I37: 149.00 | J37: 447.00 | K37: 410 | L37: GBP | M37: completed
A38: ORD-101807 | B38: 04/24/2026 | C38: customer1225@example.com | D38: UK | E38: direct | F38: FR-7781 | G38: Storm Overtrousers | H38: 2 | I38: 11.25 | J38: 22.50 | K38: 0.410 | L38: GBP | M38: refunded
A39: ORD-102879 | B39: 46111 | C39: customer1087@example.com | D39: ireland | E39: paid_search | F39: FR-7781 | G39: Storm Overtrousers | H39: 1 | I39: 149.00 | J39: 149.00 | K39: 410 | L39: GBP | M39: refunded
A40: ORD-100229 | B40: 02/14/2026 | C40: customer0706@example.com | D40: gb | E40: paid_search | F40: FR-1120 | G40: Fell Runner Cap | H40: 1 | I40: 80.10 | J40: 80.10 | K40: 85 | L40: GBP | M40: completed
...

Sheet Clean_Data
A1: order_id | B1: order_date | C1: customer_email | D1: country | E1: channel | F1: product_sku | G1: product_name | H1: quantity | I1: unit_price | J1: order_total | K1: weight | L1: currency | M1: status
A2: ORD-101805 | B2: 46100 | C2: customer0457@example.com | D2: =IF(OR(PROPER(TRIM(Raw_Data!D2))="Uk",PROPER(TRIM(Raw_Data!D2))="Gb",PROPER(TRIM(Raw_Data!D2))="United kingdom"),"United Kingdom",PROPER(TRIM(Raw_Data!D2))) -> France | E2: direct | F2: FR-9902 | G2: =SUBSTITUTE(Raw_Data!G2,"Ã©","é") -> Trekking Poles | H2: 1 | I2: 45.00 | J2: 36.00 | K2: 0.52 | L2: EUR | M2: completed
A3: ORD-102690 | B3: 46161 | C3: customer0814@example.com | D3: =IF(OR(PROPER(TRIM(Raw_Data!D3))="Uk",PROPER(TRIM(Raw_Data!D3))="Gb",PROPER(TRIM(Raw_Data!D3))="United kingdom"),"United Kingdom",PROPER(TRIM(Raw_Data!D3))) -> France | E3: social | F3: FR-2210 | G3: =SUBSTITUTE(Raw_Data!G3,"Ã©","é") -> Trail Softshell | H3: 1 | I3: 71.10 | J3: 71.10 | K3: 0.52 | L3: GBP | M3: completed
A4: ORD-101454 | B4: 46187 | C4: customer0858@example.com | D4: =IF(OR(PROPER(TRIM(Raw_Data!D4))="Uk",PROPER(TRIM(Raw_Data!D4))="Gb",PROPER(TRIM(Raw_Data!D4))="United kingdom"),"United Kingdom",PROPER(TRIM(Raw_Data!D4))) -> United Kingdom | E4: email | F4: FR-1120 | G4: =SUBSTITUTE(Raw_Data!G4,"Ã©","é") -> Fell Runner Cap | H4: 1 | I4: 45.00 | J4: 45.00 | K4: 0.085 | L4: GBP | M4: completed
A5: ORD-100450 | B5: 46235 | C5: customer0116@example.com | D5: =IF(OR(PROPER(TRIM(Raw_Data!D5))="Uk",PROPER(TRIM(Raw_Data!D5))="Gb",PROPER(TRIM(Raw_Data!D5))="United kingdom"),"United Kingdom",PROPER(TRIM(Raw_Data!D5))) -> United Kingdom | E5: organic | F5: FR-5567 | G5: =SUBSTITUTE(Raw_Data!G5,"Ã©","é") -> Merino Base Layer | H5: 1 | I5: 71.10 | J5: 71.10 | K5: 0.19 | L5: EUR | M5: completed
A6: ORD-101501 | B6: 46162 | C6: customer1397@example.com | D6: =IF(OR(PROPER(TRIM(Raw_Data!D6))="Uk",PROPER(TRIM(Raw_Data!D6))="Gb",PROPER(TRIM(Raw_Data!D6))="United kingdom"),"United Kingdom",PROPER(TRIM(Raw_Data!D6))) -> Ireland | E6: email | F6: FR-8890 | G6: =SUBSTITUTE(Raw_Data!G6,"Ã©","é") -> Summit Down Gilet | H6: 1 | I6: 21.60 | J6: 21.60 | K6: 0.38 | L6: GBP | M6: completed
A7: ORD-101788 | B7: 46095 | C7: customer0775@example.com | D7: =IF(OR(PROPER(TRIM(Raw_Data!D7))="Uk",PROPER(TRIM(Raw_Data!D7))="Gb",PROPER(TRIM(Raw_Data!D7))="United kingdom"),"United Kingdom",PROPER(TRIM(Raw_Data!D7))) -> United Kingdom | E7: organic | F7: FR-1120 | G7: =SUBSTITUTE(Raw_Data!G7,"Ã©","é") -> Fell Runner Cap | H7: 1 | I7: 45.00 | J7: 45.00 | K7: 0.085 | L7: GBP | M7: completed
A8: ORD-102657 | B8: 46137 | C8: customer1328@example.com | D8: =IF(OR(PROPER(TRIM(Raw_Data!D8))="Uk",PROPER(TRIM(Raw_Data!D8))="Gb",PROPER(TRIM(Raw_Data!D8))="United kingdom"),"United Kingdom",PROPER(TRIM(Raw_Data!D8))) -> United Kingdom | E8: social | F8: FR-1120 | G8: =SUBSTITUTE(Raw_Data!G8,"Ã©","é") -> Fell Runner Cap | H8: 3 | I8: 85.50 | J8: 256.50 | K8: 0.085 | L8: GBP | M8: refunded
A9: ORD-102047 | B9: 46162 | C9: customer0760@example.com | D9: =IF(OR(PROPER(TRIM(Raw_Data!D9))="Uk",PROPER(TRIM(Raw_Data!D9))="Gb",PROPER(TRIM(Raw_Data!D9))="United kingdom"),"United Kingdom",PROPER(TRIM(Raw_Data!D9))) -> Ireland | E9: organic | F9: FR-1120 | G9: =SUBSTITUTE(Raw_Data!G9,"Ã©","é") -> Fell Runner Cap | H9: 2 | I9: 134.10 | J9: 268.20 | K9: 0.085 | L9: EUR | M9: refunded
A10: ORD-102650 | B10: 46057 | C10: customer0013@example.com | D10: =IF(OR(PROPER(TRIM(Raw_Data!D10))="Uk",PROPER(TRIM(Raw_Data!D10))="Gb",PROPER(TRIM(Raw_Data!D10))="United kingdom"),"United Kingdom",PROPER(TRIM(Raw_Data!D10))) -> United Kingdom | E10: paid_search | F10: FR-5567 | G10: =SUBSTITUTE(Raw_Data!G10,"Ã©","é") -> Merino Base Layer | H10: 1 | I10: 24.00 | J10: 24.00 | K10: 0.19 | L10: GBP | M10: completed
A11: ORD-102734 | B11: 46069 | C11: customer0805@example.com | D11: =IF(OR(PROPER(TRIM(Raw_Data!D11))="Uk",PROPER(TRIM(Raw_Data!D11))="Gb",PROPER(TRIM(Raw_Data!D11))="United kingdom"),"United Kingdom",PROPER(TRIM(Raw_Data!D11))) -> United Kingdom | E11: paid_search | F11: FR-5567 | G11: =SUBSTITUTE(Raw_Data!G11,"Ã©","é") -> Merino Base Layer | H11: 1 | I11: 95.00 | J11: 95.00 | K11: 0.19 | L11: EUR | M11: refunded
A12: ORD-102012 | B12: 46133 | C12: customer0123@example.com | D12: =IF(OR(PROPER(TRIM(Raw_Data!D12))="Uk",PROPER(TRIM(Raw_Data!D12))="Gb",PROPER(TRIM(Raw_Data!D12))="United kingdom"),"United Kingdom",PROPER(TRIM(Raw_Data!D12))) -> United Kingdom | E12: email | F12: FR-7781 | G12: =SUBSTITUTE(Raw_Data!G12,"Ã©","é") -> Storm Overtrousers | H12: 1 | I12: 45.00 | J12: 45.00 | K12: 0.41 | L12: GBP | M12: completed
A13: ORD-102152 | B13: 46029 | C13: customer0956@example.com | D13: =IF(OR(PROPER(TRIM(Raw_Data!D13))="Uk",PROPER(TRIM(Raw_Data!D13))="Gb",PROPER(TRIM(Raw_Data!D13))="United kingdom"),"United Kingdom",PROPER(TRIM(Raw_Data!D13))) -> Ireland | E13: email | F13: FR-7781 | G13: =SUBSTITUTE(Raw_Data!G13,"Ã©","é") -> Storm Overtrousers | H13: 1 | I13: 129.00 | J13: 129.00 | K13: 0.41 | L13: GBP | M13: completed
... A3001: ORD-102825 | B3001: 46073 | C3001: customer0961@example.com | D3001: =IF(OR(PROPER(TRIM(Raw_Data!D3001))="Uk",PROPER(TRIM(Raw_Data!D3001))="Gb",PROPER(TRIM(Raw_Data!D3001))="United kingdom"),"United Kingdom",PROPER(TRIM(Raw_Data!D3001))) -> Ireland | E3001: direct | F3001: FR-9902 | G3001: =SUBSTITUTE(Raw_Data!G3001,"Ã©","é") -> Trail Softshell | H3001: 2 | I3001: 129.00 | J3001: 258.00 | K3001: 0.52 | L3001: GBP | M3001: completed
